Workbook
Name _ANO1: Parâmetros!$F$5
Name _ANO2: Parâmetros!$F$6
Name EMPRESA1: Parâmetros!$D$5
Name EMPRESA2: Parâmetros!$D$6
Name MF: Parâmetros!$D$9
Name MI: Parâmetros!$D$8

Sheet Parâmetros
A3: MAPAS FINANCEIROS - CURSO
D4: Cód. | E4: Descrição | F4: Ano
B5: Balanço | C5: Empresa N | D5: EDSON | E5: EDSON FERREIRA | F5: 2014
B6: Demonstração de Resultados | C6: Empresa N-1 | D6: EDSON | E6: EDSON FERREIRA | F6: 2015
B7: Demonstração de Fluxos de Caixa | C7: Empresa N-2 | D7: EDSON | E7: EDSON FERREIRA | F7: 2016
C8: Mês Inicial | D8: 0
C9: Mês Final | D9: 15
B12: 4 - Imobilização Corpórea
B13: 5 - Imobilizado Incorpóreo
B14: 6 - Invest. Subs. e Associadas
B15: 7 - Outros Activos Financeiros
B16: 8 - Existências
B17: 9 - Out. Act não C. e C. a Rec.
B18: 10 - Disponibilidades
B19: 11 - Outros Activos Correntes
B20: 12 - Capital
B21: 13 - Reservas
B22: 14 - Resultados Transitados
B23: 15 - Emp. Corr. não Correntes.
... B45: Extras

Sheet Balanço
A2: BALANÇO 2012
E3: Valores expressos em
E4: AKZ
A6: Designação | B6: Notas | C6: Contas | D6: Exercício
D7: 2015 | E7: 2014
A8: ACTIVO | I8: 2014 | K8: 2011
A9: Activo não corrente:
A10: Imobilizações corpóreas | B10: 4 | C10: 11+141+142+147-181(Mês 0a15) | D10: =I10+I18+I19-I22 -> 0 | E10: 0 | G10: I10 | H10: 11 | J10: 11
A11: Imobilizações incorpóreas | B11: 5 | C11: 12+148-182(Mês 0a15) | D11: =I11-I23 -> 0 | E11: 0 | G11: I11 | H11: 12 | J11: 12
A12: Investimentos em subsidiárias e associadas | B12: 6 | C12: 131+132+148-191-192(Mês 0a15) | D12: =I12+I13+I21-I24-I25+I14 -> 0 | E12: 0 | G12: I12 | H12: 131 | J12: 131
A13: Outros activos financeiros | B13: 7 | C13: 133+134+135+139+148-193-194+199(Mês 0a15) | D13: =I15+I16+I17+I21-I26-I27+I28 -> 0 | E13: 0 | G13: I13 | H13: 132 | J13: 132
A14: Outros activos não correntes | B14: 9 | C14: saldos Devedores>1 ano 31+329(sl.dev)+34(sl.dev)+35(sl.dev)+372+3791-381-382-383-389(dividas com mais 1 ano)(Mês 0a15) | D14: 0 | E14: 0 | G14: I14 | H14: 133 | J14: 133
C15: Soma da I a V | D15: =SUM(D10:D14) -> 0 | E15: =SUM(E10:E14) -> 0 | G15: I15 | H15: 134 | J15: 134
G16: I16 | H16: 135 | J16: 135
A17: Activo corrente: | G17: I17 | H17: 139 | J17: 139
A18: Existências | B18: 8 | C18: 22+23+24+25+26+27-29(Mês 0a15) | D18: =I30+I33 -> 0 | E18: 0 | G18: I18 | H18: 141 | J18: 141
A19: Contas a receber | B19: 9 | C19: 31+329(sl.dev)+34(sl.dev)+35(sl.dev)+372+3791-381-382-28+383-389(dividas com menos de 1 ano)(Mês 0a15) | D19: =I37+I47+I49+I51+I59+I61+I63-I65+I40 -> 0 | E19: 0 | G19: I19 | H19: 142 | J19: 142
A20: Disponibilidades | B20: 10 | C20: 41+42+43+44+45+46+47+48-49(Mês 0a15) | D20: =+I75+I76 -> 100000 | E20: 0 | G20: I20 | H20: 147 | J20: 147
A21: Outros activos correntes | B21: 11 | C21: 374+373+(Mês 0a15) | D21: 0 | E21: 0 | G21: I21 | H21: 148 | J21: 148
C22: Soma da VI a IX | D22: =SUM(D18:D21) -> 100000 | E22: =SUM(E18:E21) -> 0 | G22: I22 | H22: 181 | J22: 181
G23: I23 | H23: 182 | J23: 182
A24: Total do activo | D24: =+D22+D15 -> 100000 | E24: =E22+E15 -> 0 | G24: I24 | H24: 191 | J24: 191
G25: I25 | H25: 192 | J25: 192
G26: I26 | H26: 193 | J26: 193
A27: CAPITAL PRÓPRIO E PASSIVO | G27: I27 | H27: 194 | J27: 194
A28: Capital próprio: | G28: I28 | H28: 199 | J28: 199
A29: Capital | B29: 12 | C29: 51+52+53+54(Mês 0a15) | D29: =I79 -> 100000 | E29: 0 | G29: I29 | H29: 22 | J29: 22
A30: Reservas | B30: 13 | C30: 55+56+57+58+59(Mês 0a15) | D30: =I86 -> 0 | E30: 0 | G30: I30 | H30: 21 | J30: 23
A31: Resultados transitados | B31: 14 | C31: 81(Mês 0a15) | D31: =I88 -> 0 | E31: 0 | G31: I31 | H31: 24 | J31: 24
A32: Resultados do exercício | C32: 88(Mês 0a15) | D32: =+I89 -> -12500 | E32: 0 | G32: I32 | H32: 25 | J32: 25
C33: Soma da X a XIII | D33: =SUM(D29:D32) -> 87500 | E33: =SUM(E29:E32) -> 0 | G33: I33 | H33: 26 | J33: 26
G34: I34 | H34: 27 | J34: 27
G35: I35 | H35: 28 | J35: 28
A36: Passivo não corrente: | G36: I36 | H36: 29 | J36: 29
A37: Empréstimos de médio e longo prazos | B37: 15 | C37: 3312+3322+3332+3392(dividas com mais 1 ano)(Mês0 a 15) | D37: 0 | E37: 0 | G37: I37 | H37: 311...318 | J37: 311...318
A38: Impostos diferidos | B38: 16 | C38: Suspensa | D38: 0 | E38: 0 | G38: I38 | H38: 319 | J38: 319
A39: Provisões para pensões | B39: 17 | C39: 391(Mês 0a15) | D39: =I68 -> 0 | E39: =K68 -> 0 | G39: I39 | H39: 321…328 | J39: 321…328
A40: Provisões para outros riscos e encargos | B40: 18 | C40: 392+393+394+399(Mês 0a15) | D40: =I69+I70+I71+I72 -> 0 | E40: =K69+K70+K71+K72 -> 0 | G40: I40 | H40: 329 | J40: 329
A41: Outros passivos não correntes | B41: 19 | C41: 32+319(sl.cred)+34(sl.cred)+35(sl.cred)+371+3792(dividas com mais 1 ano)(Mês 0a15) | D41: =+I55 -> 0 | E41: 0 | G41: I41 | H41: 3311 | J41: 3311
C42: Soma da XIV a XVIIII | D42: =SUM(D37:D41) -> 0 | E42: =SUM(E37:E41) -> 0 | G42: I42 | H42: 3312 | J42: 3312
...

Sheet Demonstração de Resultados
B2: DEMONSTRAÇÃO DE RESULTADOS - 2018
B3: (por natureza)
I4: 2018
C5: Valores expressos em | F5: AKZ
B6: PRIBEM | I6: 61
A7: Contador | B7: Designação | C7: Notas | D7: Contas | E7: Exercício | I7: 62
E8: 2018 | F8: 2017 | I8: 63
A9: I | B9: Vendas | C9: 22 | D9: 61(Mês 1a13) | E9: =+J6 -> 0 | F9: 0 | I9: 64
B10: Prestações de serviços | C10: 23 | D10: 62(Mês 1a13) | E10: =+J7 -> 0 | F10: 0 | I10: 65
A11: III | B11: Outros proveitos operacionais | C11: 24 | D11: 63(Mês 1a13) | E11: =J8 -> 0 | F11: 0 | I11: 66
D12: 1-Soma da I a III | E12: =+E10+E9 -> 0 | F12: =SUM(F9:F11) -> 0 | I12: 67
A13: IV | B13: Variação nos produtos acabados e produtos em vias de fabrico | C13: 25 | D13: 64(Mês 1a13) | E13: =J9 -> 0 | F13: 0 | I13: 68
A14: V | B14: Trabalhos para a própria empresa | C14: 26 | D14: 65(Mês 1a13) | E14: 0 | F14: 0 | I14: 69
A15: VI | B15: Custos das mercadorias vendidas e das matérias-primas e subsidiárias consumidas | C15: 27 | D15: 71(Mês 1a13) | E15: =+J15 -> 0 | F15: 0 | I15: 71
A16: VII | B16: Custos com o pessoal | C16: 28 | D16: 72(Mês 1a13) | E16: =+J16 -> 0 | F16: 0 | I16: 72
A17: VIII | B17: Amortizações | C17: 29 | D17: 73(Mês 1a13) | E17: =+J17 -> 0 | F17: 12500 | I17: 73
A18: IX | B18: Outros custos e perdas operacionais | C18: 30 | D18: 75(Mês 1a13) | E18: =+J19 -> 0 | F18: 0 | I18: 74
B19: Resultado operacionai | D19: 2-Soma da I a V-(VIaIX) | E19: =+E12-E13-E14-E15-E16-E17-E18 -> 0 | F19: =+F12-F17-F18 -> -12500 | I19: 75
I20: 76
A21: X | B21: Resultados financeiros | C21: 31 | D21: 66-76(Mês 1a13) | E21: =+J20 -> 0 | F21: -2416.8 | I21: 77
A22: XI | B22: Resultados de filiais e associadas | C22: 32 | D22: 67-77(Mês 1a13) | E22: 0 | F22: =K12-K21 -> 0 | I22: 78
A23: XII | B23: Resultados não operacionais | C23: 33 | D23: 68-78(Mês 1a13) | E23: =J13-J22 -> 0 | F23: 0 | I23: 79
B24: Resultado antes de impostos | D24: 3-Soma da 2 + (XaXII) | E24: =SUM(E19:E23) -> 0 | F24: =SUM(F19:F23) -> -14916.8
A26: XIII | B26: Imposto sobre o rendimento | C26: 35 | D26: 871(Mês 15-15) | F26: 0
B27: Resultado líquido das actividades correntes | D27: 4-Soma da 3 -XIII | F27: =-F26+F24 -> -14916.8
A29: XIV | B29: Resultados extraordinários | C29: 34 | D29: 69-79(Mês 1a13) | E29: =J14-J23 -> 0 | F29: 0
A30: XV | B30: Imposto sobre o rendimento | C30: 35 | D30: 872(Mês 15-15) | E30: 0 | F30: 0
B32: Resultado líquido do exercício | D32: 5-Soma da 4 +XIV+XV | E32: =E24-E26+E29 -> 0 | F32: =SUM(F27:F30) -> -14916.8
A34: Obs: | B34: Todos os valores totais (somas) quando negativos deve-se analisar as situações das restantes contas
B38: Gerência | E38: Técnico Oficial de Contas

Sheet 4 - Imobilização Corpórea
A1: 4. Imobilização corpórea:
A3: 4.1 Composição:
A4: Rubricas | C4: Valor bruto | D4: Amortizações acumuladas | E4: Valor líquido
A7: Terrenos e recursos naturais | B7: 111-1811 | C7: 9500000 | D7: 4625162.2 | E7: =C7-D7 -> 4874837.8
A8: Edifícios e outras construções | B8: 112-1812 | C8: 41500600 | D8: 0 | E8: =C8-D8 -> 41500600
A9: Equipamento básico | B9: 113-1813 | C9: 0 | D9: 0 | E9: =C9-D9 -> 0
A10: Equipamento de transporte | B10: 114-1814 | C10: 0 | D10: 0 | E10: =C10-D10 -> 0
A11: Equipamento administrativo | B11: 115-1815 | C11: 0 | D11: 0 | E11: =C11-D11 -> 0
A12: Outras imobilizações corpóreas | B12: 119-1819 | C12: 0 | D12: 0 | E12: =C12-D12 -> 0
A13: Taras e vasilhame | B13: 116-1816 | C13: 0 | D13: 0 | E13: =C13-D13 -> 0
A14: Imobilizado em Curso | B14: 141/142 | C14: 0 | D14: 0 | E14: =C14-D14 -> 0
A15: Adiant. Por conta de imobili. corp. | B15: 147 | C15: 0 | D15: 0 | E15: =C15-D15 -> 0
A17: Total | C17: =SUM(C7:C15) -> 51000600 | D17: =SUM(D7:D15) -> 4625162.2 | E17: =SUM(E7:E15) -> 46375438
A19: 4.2 Composição por critérios do quadro seguinte
A20: Rubricas | C20: Valor líquido | F20: Extra Contabilistico Ou Imobilizado
C21: Custo histórico | D21: Valor de reavaliação | E21: Total
A22: Terrenos e recursos naturais | B22: 111-1811 | E22: =C22-D22 -> 0
A23: Edifícios e outras construções | B23: 112-1812 | E23: =C23-D23 -> 0
A24: Equipamento básico | B24: 113-1813 | E24: =C24-D24 -> 0
A25: Equipamento de transporte | B25: 114-1814 | E25: =C25-D25 -> 0
A26: Equipamento administrativo | B26: 115-1815 | E26: =C26-D26 -> 0
A27: Taras e vasilhame | B27: 119-1819 | E27: =C27-D27 -> 0
A28: Outras imobilizações corpóreas | B28: 116-1816 | E28: =C28-D28 -> 0
A29: Imobilizado em Curso | B29: 141/142 | E29: =C29-D29 -> 0
A30: Adiant. Por conta de imobili. corp. | B30: 147 | E30: =C30-D30 -> 0
A31: Total | C31: =SUM(C22:C30) -> 0 | D31: =SUM(D22:D30) -> 0 | E31: =SUM(E22:E30) -> 0
A33: 4.3 Movimentos, ocorridos durante o exercício, no valor bruto: | G33: Vl. Manual
A34: Rubricas | C34: Saldo inicial | D34: Reavaliações | E34: Aumentos | F34: Alienações | G34: Abates/ /transf. | H34: Saldo final
A35: Terrenos e recursos naturais | B35: 111 | C35: 0 | D35: 0 | E35: 0 | F35: 0 | G35: 0 | H35: =+C35+D35+E35-F35+G35 -> 0
A36: Edifícios e outras construções | B36: 112 | C36: 0 | D36: 0 | E36: 0 | F36: 0 | G36: 0 | H36: =+C36+D36+E36-F36+G36+0 -> 0
A37: Equipamento básico | B37: 113 | C37: 0 | D37: 0 | E37: 0 | F37: 0 | G37: 0 | H37: =+C37+D37+E37+F37-G37+0 -> 0
A38: Equipamento de transporte | B38: 114 | C38: 0 | D38: 0 | E38: 0 | F38: 0 | G38: 0 | H38: =+C38+D38+E38+F38+G38+0 -> 0
A39: Equipamento administrativo | B39: 115 | C39: 0 | D39: 0 | E39: 0 | F39: 0 | G39: 0 | H39: =+C39+D39+E39-F39+G39 -> 0
A40: Taras e vasilhame | B40: 119 | C40: 0 | D40: 0 | E40: 0 | F40: 0 | G40: 0 | H40: =+C40+D40+E40-F40+G40 -> 0
A41: Outras imobilizações corpóreas | B41: 116 | C41: 0 | D41: 0 | E41: 0 | F41: 0 | G41: 0 | H41: =+C41+D41+E41+F41-G41+0 -> 0
A42: Imobilizado em Curso | B42: 141/142 | C42: 0 | D42: 0 | E42: 0 | F42: 0 | G42: 0 | H42: =+C42+D42+E42-F42+G42 -> 0
A43: Adiant. Por conta de imobili. corp. | B43: 147 | C43: 0 | D43: 0 | E43: 0 | F43: 0 | G43: 0 | H43: =+C43+D43+E43-F43+G43+0 -> 0
A45: Total | C45: =SUM(C35:C43) -> 0 | D45: =SUM(D35:D43) -> 0 | E45: =SUM(E35:E43) -> 0 | F45: =SUM(F35:F43) -> 0 | G45: 0 | H45: =SUM(H35:H43) -> 0
A47: 4.4 Movimentos, ocorridos durante o exercício, nas amortizações acumuladas:
A48: Rubricas | C48: Saldo inicial | D48: Reavaliações | E48: Reforço | F48: Alienações | G48: Abates/ /transf. | H48: Saldo final
...

Sheet 5 - Imobilizado Incorpóreo
A1: blu
A3: 5.1 Composição:
A4: Rubricas | C4: Valor bruto | D4: Amortizações acumuladas | E4: Valor líquido
A6: Trespasses | B6: 121-1821 | C6: 0 | D6: 0 | E6: =C6-D6 -> 0
A7: Despesas de desenvolvimento (a) | B7: 122-1822 | C7: 0 | D7: 0 | E7: =C7-D7 -> 0
A8: Propriedade industrial e outros direitos e contratos | B8: 123-1823 | C8: 0 | D8: 0 | E8: =C8-D8 -> 0
A9: Despesas de constituição (b) | B9: 124-1824 | C9: 281509 | D9: 93826.95 | E9: =C9-D9 -> 187682.05
A10: Outras imobilizações incorpóreas | B10: 129-1829 | C10: 0 | D10: 0 | E10: =C10-D10 -> 0
A12: Total | C12: =SUM(C6:C10) -> 281509 | D12: =SUM(D6:D10) -> 93826.95 | E12: =SUM(E6:E10) -> 187682.05
A14: (a) As despesas de desenvolvimento referem-se a: Descrever a natureza
A15: (b) AS despesas de constituição referem-se a: Descrever a natureza
A17: 5.2 Movimentos, ocorridos durante o exercício, no valor bruto
A18: Rubricas | C18: Saldo inicial | D18: Aumentos | E18: Diminuições | F18: Saldo final
A20: Trespasses | B20: 121 | C20: 0 | D20: 0 | E20: 0 | F20: =+C20+D20-E20 -> 0
A21: Despesas de desenvolvimento | B21: 122 | C21: 0 | D21: 0 | E21: 0 | F21: =+C21+D21-E21 -> 0
A22: Propriedade industrial e outros direitos e contratos | B22: 123 | C22: 0 | D22: 0 | E22: 0 | F22: =+C22+D22-E22 -> 0
A23: Despesas de constituição | B23: 124 | C23: 0 | D23: 0 | E23: 0 | F23: =+C23+D23-E23 -> 0
A24: Outras imobilizações incorpóreas | B24: 129 | C24: 0 | D24: 0 | E24: 0 | F24: =+C24+D24-E24 -> 0
A26: Total | C26: =SUM(C20:C24) -> 0 | D26: =SUM(D20:D24) -> 0 | E26: =SUM(E20:E24) -> 0 | F26: =SUM(F20:F24) -> 0
A28: 5.3 Movimentos, ocorridos durante o exercício, nas amortizações acumuladas:
A29: Rubricas | C29: Saldo inicial | D29: Aumentos | E29: Diminuições | F29: Saldo final
A31: Trespasses | B31: 1821 | C31: 0 | D31: 0 | E31: 0 | F31: =+C31+D31-E31 -> 0
A32: Despesas de desenvolvimento | B32: 1822 | C32: 0 | D32: 0 | E32: 0 | F32: =+C32+D32-E32 -> 0
A33: Propriedade industrial e outros direitos e contratos | B33: 1823 | C33: 0 | D33: 0 | E33: 0 | F33: =+C33+D33-E33 -> 0
A34: Despesas de constituição | B34: 1824 | C34: 0 | D34: 0 | E34: 0 | F34: =+C34+D34-E34 -> 0
A35: Outras imobilizações incorpóreas | B35: 1825 | C35: 0 | D35: 0 | E35: 0 | F35: =+C35+D35-E35 -> 0
A37: Total | C37: =SUM(C31:C35) -> 0 | D37: =SUM(D31:D35) -> 0 | E37: =SUM(E31:E35) -> 0 | F37: =SUM(F31:F35) -> 0

Sheet 6 - Invest. Subs. e Associadas
A1: 6. Investimentos em subsidiários e associadas:
A3: 6.1 Composição:
A4: Rubricas | C4: Valor bruto | D4: Amortizações acumuladas | E4: Valor líquido
A6: Subsidiárias:
A7: Partes de capital (a) | B7: 1311/1911 | C7: 0 | D7: 0 | E7: =+C7-D7 -> 0
A8: Obrigações e outros títulos de participação | B8: 1312/1912 | C8: 0 | D8: 0 | E8: =+C8-D8 -> 0
A9: Empréstimos | B9: 1313/1913 | C9: 0 | D9: 0 | E9: =+C9-D9 -> 0
A10: Adiantamentos por conta | B10: 1491 | C10: 0 | E10: =+C10-D10 -> 0
A12: Associadas:
A13: Partes de capital (a) | B13: 1321/1921 | C13: 0 | D13: 0 | E13: =+C13-D13 -> 0
A14: Obrigações e outros títulos de participação | B14: 1322/1922 | C14: 0 | D14: 0 | E14: =+C14-D14 -> 0
A15: Empréstimos | B15: 1323/1923 | C15: 0 | D15: 0 | E15: =+C15-D15 -> 0
A16: Adiantamentos por conta | B16: 1492 | C16: 0
A18: Total | C18: =SUM(C7:C16) -> 0 | D18: =SUM(D7:D16) -> 0 | E18: =SUM(E7:E16) -> 0
A20: (a) Partes de capital em subsidiárias
A21: (b) Partes de capital em associadas
A24: Subsidiárias | C24: Contas da subsidiária | E24: % de participação | F24: % de votos detidos | G24: Valores detidos | H24: Quantia bruta registada
C25: Capitais próprios | D25: Resultados do período
A27: Descrever, por subsidiária, os seguintes dados:
A28: Firma
A29: Forma Jurídica
A30: Sede
A31: Total | C31: =SUM(C27:C30) -> 0 | D31: =SUM(D27:D30) -> 0 | G31: =SUM(G27:G30) -> 0
A34: Subsidiárias | C34: Contas da subsidiária | E34: % de participação | F34: % de votos detidos | G34: Valores detidos | H34: Quantia bruta registada
C35: Capitais próprios | D35: Resultados do período
A37: Descrever, por associados, os seguintes dados:
A38: Firma
A39: Forma Jurídica
A40: Sede
A41: Total | C41: =SUM(C37:C40) -> 0 | D41: =SUM(D37:D40) -> 0 | G41: =SUM(G37:G40) -> 0
A44: 6.2 Movimentos, ocorridos durante o exercício, nas provisões:
A45: Rubricas | C45: Saldo inicial | D45: Aumentos | E45: Diminuições | F45: Saldo final
A47: Subsidiárias:
A48: Partes de capital (a) | B48: 1911 | C48: 0 | D48: 0 | E48: 0 | F48: =+C48+D48-E48 -> 0
A49: Obrigações e outros títulos de participação | B49: 1912 | C49: 0 | D49: 0 | E49: 0 | F49: =+C49+D49-E49 -> 0
A50: Empréstimos | B50: 1913 | C50: 0 | D50: 0 | E50: 0 | F50: =+C50+D50-E50 -> 0
A51: Adiantamentos por conta
A53: Associadas:
A54: Partes de capital (a) | B54: 1921 | C54: 0 | D54: 0 | E54: 0 | F54: =+C54+D54-E54 -> 0
A55: Obrigações e outros títulos de participação | B55: 1922 | C55: 0 | D55: 0 | E55: 0 | F55: =+C55+D55-E55 -> 0
...

Sheet 7 - Outros Activos Financeiros
A1: 7. Outros activos financeiros:
A3: 7.1 Composição:
A4: Rubricas | C4: Valor bruto | D4: Amortizações acumuladas | E4: Provisões | F4: Valor líquido
A6: Investimentos em outras empresas | B6: 133/193 | C6: 0 | E6: 0 | F6: =+C6-D6-E6 -> 0
A7: Investimentos em imóveis | B7: 134/183 | C7: 0 | D7: 0 | F7: =+C7-D7-E7 -> 0
A8: Fundos | B8: 135/194 | C8: 0 | E8: 0 | F8: =+C8-D8-E8 -> 0
A9: Outros investimentos financeiros | B9: 139/199 | C9: 0 | E9: 0 | F9: =+C9-D9-E9 -> 0
A11: Total | C11: =SUM(C6:C9) -> 0 | D11: =SUM(D6:D9) -> 0 | E11: =SUM(E6:E9) -> 0 | F11: =SUM(F6:F9) -> 0
A14: 7.2 Movimentos, ocorridos durante o exercício, nos investimentos em imóveis:
A15: Rubricas | C15: Saldo inicial | D15: Aumentos | F15: Reduções | H15: Total
D16: Aquisições | E16: Reavaliações | F16: Alienações | G16: Reavaliações
A18: Valor bruto | B18: 134 | C18: 0 | D18: 0 | E18: 0 | F18: 0 | G18: 0 | H18: =+C18+D18+E18-F18-G18 -> 0
A19: Amortizações acumuladas | B19: 183 | C19: 0 | D19: 0 | E19: 0 | F19: 0 | G19: 0 | H19: =+C19+D19+E19-F19-G19 -> 0
A21: Total | C21: =+C18-C19 -> 0 | D21: =+D18-D19 -> 0 | E21: =+E18-E19 -> 0 | F21: =+F18-F19 -> 0 | G21: =+G18-G19 -> 0 | H21: =+H18-H19 -> 0
A24: 7.3 Movimentos, ocorridos durante o exercício, nas provisões:
A25: Rubricas | C25: Saldo inicial | D25: Aumentos | E25: Diminuições | F25: Saldo final
A27: Investimentos em outras empresas | B27: 193 | C27: 0 | D27: 0 | E27: 0 | F27: =+C27+D27-E27 -> 0
A28: Fundos | B28: 194 | C28: 0 | D28: 0 | E28: 0 | F28: =+C28+D28-E28 -> 0
A29: Outros investimentos financeiros | B29: 199 | C29: 0 | D29: 0 | E29: 0 | F29: =+C29+D29-E29 -> 0
A30: Total | C30: =SUM(C27:C29) -> 0 | D30: =SUM(D27:D29) -> 0 | E30: =SUM(E27:E29) -> 0 | F30: =SUM(F27:F29) -> 0
A33: 7.4 Restrições existentes:
A34: Rubricas | C34: Valor líquido dos investimentos
C35: Em poder de terceiros | D35: Implantados em propriedade alheia | E35: Localizados no estrangeiro | F35: Reversíveis (a) | G35: Penhorados (b) | H35: Hipotecados (b)
A38: Investimentos em imóveis | B38: 134
A40: (a) Indicar as datas e razões da reversibilidade.
A41: (b) Indicar os passivos com os quais se relacionam as garantias.
A44: Rubricas | C44: Penhoras e outras restrições
C45: Quantidade de títulos | D45: Valor liquido
A47: Investimentos em outras empresas | B47: 133
A48: Fundos | B48: 135
A49: Outros investimentos financeiros | B49: 139
A50: Total | D50: =+D47-D49 -> 0
A52: (a) Indicar os passivos com os quais se relacionam as garantias

Sheet 8 - Existências
A1: 8. Existências:
A3: 8.1 Composição:
A4: Rubricas | C4: Valor Bruto | D4: Provisões acumuladas | E4: Valor liquido
A7: Matérias-primas, subsidiárias e de consumo | B7: 22/292 | C7: 0 | D7: 0 | E7: =+C7-D7 -> 0
A8: Produtos e trabalhos em curso | B8: 23/293 | C8: 0 | D8: 0 | E8: =+C8-D8 -> 0
A9: Produtos acabados e intermédios | B9: 24/294 | C9: 0 | D9: 0 | E9: =+C9-D9 -> 0
A10: Subprodutos, desperdícios, resíduos e refugos | B10: 25/295 | C10: 0 | D10: 0 | E10: =+C10-D10 -> 0
A11: Mercadorias | B11: 26/296 | C11: 0 | D11: 0 | E11: =+C11-D11 -> 0
A12: Matérias-primas, mercadorias e matérias em trânsito | B12: 27/297 | C12: 0 | D12: 0 | E12: =+C12-D12 -> 0
A14: Total | C14: =SUM(C7:C12) -> 0 | D14: =SUM(D7:D12) -> 0 | E14: =SUM(E7:E12) -> 0
A18: 8.2 Movimentos, ocorridos durante o exercício, nas provisões:
A19: Rubricas | C19: Saldo inicial | D19: Aumentos | E19: Diminuições | F19: Saldo final
A21: Matérias-primas, subsidiárias e de consumo | B21: 292 | C21: 0 | D21: 0 | E21: 0 | F21: =+C21+D21-E21 -> 0
A22: Produtos e trabalhos em curso | B22: 293 | C22: 0 | D22: 0 | E22: 0 | F22: =+C22+D22-E22 -> 0
A23: Produtos acabados e intermédios | B23: 294 | C23: 0 | D23: 0 | E23: 0 | F23: =+C23+D23-E23 -> 0
A24: Subprodutos, desperdícios, resíduos e refugos | B24: 295 | C24: 0 | D24: 0 | E24: 0 | F24: =+C24+D24-E24 -> 0
A25: Mercadorias | B25: 296 | C25: 0 | D25: 0 | E25: 0 | F25: =+C25+D25-E25 -> 0
A26: Matérias-primas, mercadorias e matérias em trânsito | B26: 297 | C26: 0 | D26: 0 | E26: 0 | F26: =+C26+D26-E26 -> 0
A27: Total | C27: =SUM(C21:C26) -> 0 | D27: =SUM(D21:D26) -> 0 | E27: =SUM(E21:E26) -> 0 | F27: =SUM(F21:F26) -> 0
A30: 8.3 Restrições existentes:
A31: Rubricas | C31: Penhores para garantia de passivos (valor líquido)
A34: Matérias-primas, subsidiárias e de consumo | B34: 22
A35: Produtos e trabalhos em curso | B35: 23
A36: Produtos acabados e intermédios | B36: 24
A37: Subprodutos, desperdícios, resíduos e refugos | B37: 25
A38: Mercadorias | B38: 26
A39: Matérias-primas, mercadorias e matérias em trânsito | B39: 27
A40: Total
A43: 8.4 Informações relativas a contratos plurianuais em curso:
A44: Rubricas | C44: Valores
C45: Totais até à data | D45: Reconhecidos em resultados | G45: Por reconhecer (b)
D46: Em anos anteriores | E46: No exercício | F46: Total
A48: Custos dos contratos | F48: =+D48+E48 -> 0
A49: Facturado a clientes | F49: =+D49+E49 -> 0
A50: A facturar a a clientes (a) | F50: =+D50+E50 -> 0
A51: Prejuízos estimados | F51: =+D51+E51 -> 0
A52: Total | C52: =SUM(C48:C51) -> 0 | D52: =SUM(D48:D51) -> 0 | E52: =SUM(E48:E51) -> 0 | F52: =SUM(F48:F51) -> 0 | G52: =SUM(G48:G51) -> 0
A54: (a) Considerados como outros activos correntes (ver nota 11) por se referir a trabalho executados que se encontra por facturar
A55: (b) Não foram reconhecidos em resultados por se referirem a:
A58: Rubricas | C58: Custos incorridos que não respeitam a trabalho executado | D58: Facturação relativa a adiantamentos | E58: Facturação em excesso do trabalho executado | F58: Total
...

Sheet 9 - Out. Act não C. e C. a Rec.
A1: 9. Outros activos não correntes e contas a receber
A3: 9.1 composição:
A4: Rubricas | C4: Corrente | D4: Não corrente
D5: Vencível até 5 anos | E5: Vencível a mais de 5 anos | F5: Total
A7: Valor bruto:
A9: Clientes - Correntes | B9: 311 | C9: 0 | D9: 0 | E9: 0 | F9: =+D9-E9 -> 0
A10: Clientes - títulos a receber | B10: 312 | C10: 0 | D10: 0 | E10: 0 | F10: =+D10-E10 -> 0
A11: Clientes de cobrança duvidosa | B11: 318 | C11: 0 | D11: 0 | E11: 0 | F11: =+D11-E11 -> 0
A12: Fornecedores - saldos devedores | B12: 329 | C12: 0 | D12: 0 | E12: 0 | F12: =+D12-E12 -> 0
A13: Estado | B13: 34 | C13: 0 | D13: 0 | E13: 0 | F13: =+D13-E13 -> 0
A14: Participantes e participadas | B14: 35 | C14: 0 | D14: 0 | E14: 0 | F14: =+D14-E14 -> 0
A15: Pessoal | B15: 36 | C15: 0 | D15: 0 | E15: 0 | F15: =+D15-E15 -> 0
A16: Devedores - vendas de imobilizado | B16: 372 | C16: 0 | D16: 0 | E16: 0 | F16: =+D16-E16 -> 0
A17: Outros devedores | B17: 3791 | C17: 0 | D17: 0 | E17: 0 | F17: =+D17-E17 -> 0
A18: Provisões para cobranças duvidosas | B18: 38 | C18: 100000 | D18: 0 | E18: 0 | F18: =+D18-E18 -> 0
A20: Total | C20: =+C18 -> 100000 | D20: =SUM(D9:D18) -> 0 | E20: =SUM(E9:E18) -> 0 | F20: =SUM(F9:F18) -> 0
A23: 9.2 Movimentos, ocorridos durante o exercício, nas provisões:
A24: Rubricas | C24: Saldo inicial | D24: Aumentos | E24: Diminuições | F24: Saldo final
A26: Clientes - Correntes | B26: 311 | C26: 0 | D26: 0 | E26: 0 | F26: =+C26+D26-E26 -> 0
A27: Clientes -- títulos a receber | B27: 312 | C27: 0 | D27: 0 | E27: 0 | F27: =+C27+D27-E27 -> 0
A28: Clientes de cobrança duvidosa | B28: 318 | C28: 0 | D28: 0 | E28: 0 | F28: =+C28+D28-E28 -> 0
A29: Fornecedores -- saldos devedores | B29: 329 | C29: 0 | D29: 0 | E29: 0 | F29: =+C29+D29-E29 -> 0
A30: Estado | B30: 34 | C30: 0 | D30: 0 | E30: 0 | F30: =+C30+D30-E30 -> 0
A31: Participantes e participadas | B31: 35 | C31: 0 | D31: 0 | E31: 0 | F31: =+C31+D31-E31 -> 0
A32: Pessoal | B32: 36 | C32: 0 | D32: 0 | E32: 0 | F32: =+C32+D32-E32 -> 0
A33: Devedores -- vendas de imobilizado | B33: 372 | C33: 0 | D33: 0 | E33: 0 | F33: =+C33+D33-E33 -> 0
A34: Outros devedores | B34: 3791 | C34: 0 | D34: 0 | E34: 0 | F34: =+C34+D34-E34 -> 0
A36: Total | C36: =SUM(C26:C34) -> 0 | D36: =SUM(D26:D34) -> 0 | E36: =SUM(E26:E34) -> 0 | F36: =SUM(F26:F34) -> 0

Sheet 10 - Disponibilidades
A1: 10. Disponibilidades:
A3: 10.1 Composição:
A4: Rubricas | C4: 2015 | D4: 2014
A6: Títulos negociáveis | B6: 41 | C6: 0 | D6: 0
A7: Depósitos a prazo (curto prazo) | C7: 0 | D7: 0
A8: Saldos em bancos | B8: 42/43/44 | C8: 0 | D8: 0
A9: Caixa | B9: 45 | C9: 300000 | D9: 0
A10: Provisões | B10: 49 | C10: 0 | D10: 0
A12: Total | C12: =SUM(C6:C9)-C10 -> 300000 | D12: =SUM(D6:D9)-D10 -> 0
A15: 10.2 Movimentos, ocorridos durante o exercício, nas provisões:
A16: Rubricas | C16: Saldo inicial | D16: Aumentos | E16: Diminuições | F16: Saldo final
A18: Provisões para títulos negociáveis | B18: 491 | C18: 0 | D18: 0 | E18: 0 | F18: =+C18+D18-E18 -> 0
A19: Provisões para outras aplicações de tesouraria | B19: 492 | C19: 0 | D19: 0 | E19: 0 | F19: =+C19+D19-E19 -> 0
A21: Total | C21: =SUM(C18:C19) -> 0 | D21: =SUM(D18:D19) -> 0 | E21: =SUM(E18:E19) -> 0 | F21: =SUM(F18:F19) -> 0
A23: 10.3 Restrições existentes:
A24: Rubricas | C24: Penhores para garantia de passivos (valor líquido) | D24: Outras restrições (valor líquido)
A28: Títulos negociáveis | B28: 41
A29: Saldos em bancos | B29: 42/43/44
A30: Caixa | B30: 45
A31: Total | C31: =SUM(C29:C30) -> 0 | D31: =SUM(D29:D30) -> 0

Sheet 11 - Outros Activos Correntes
A1: 11. Outros activos correntes:
A3: 11.1 Composição:
A4: Rubricas | C4: 2012 | D4: 2011
A7: Contratos plurienais em curso (Nota 8.4) | C7: 0 | D7: 0
A8: Encargos a repartir por exercícios futuros | C8: 0 | D8: 0
A10: Total | C10: =SUM(C7:C8) -> 0 | D10: =SUM(D7:D8) -> 0

Sheet 12 - Capital
A1: 12. Capital
A3: 12.1 Composição e movimento no período:
A4: Rubricas | C4: Saldo inicial | D4: Aumentos | E4: Diminuições | F4: Saldo final
A6: Capital | B6: 51 | C6: 100000 | D6: 0 | E6: 0 | F6: =+C6+D6-E6 -> 100000
A7: Acções/quotas próprias | B7: 52 | C7: 0 | D7: 0 | E7: 0 | F7: =+C7+D7-E7 -> 0
A8: Prémios de emissão | B8: 53 | C8: 0 | D8: 0 | E8: 0 | F8: =+C8+D8-E8 -> 0
A9: Prestações suplementares | B9: 54 | C9: 0 | D9: 0 | E9: 0 | F9: =+C9+D9-E9 -> 0
A11: Total | C11: =SUM(C6:C9) -> 100000 | D11: =SUM(D6:D9) -> 0 | E11: =SUM(E6:E9) -> 0 | F11: =SUM(F6:F9) -> 100000
A14: 12.2 Capital:
A15: Rubricas | C15: Saldo inicial | D15: Aumentos (a)(b) | E15: Diminuições | F15: Saldo final (c)
A17: Sócios/accionistas com participação superior a 20% | F17: =+C17+D17-E17 -> 0
A18: Indicar nome ou firma
A19: Outros sócios/accionistas
A20: Total | C20: =SUM(C17:C19) -> 0 | D20: =SUM(D17:D19) -> 0 | E20: =SUM(E17:E19) -> 0 | F20: =SUM(F17:F19) -> 0
A22: (a) Aumentos de capital
A23: Indicar a forma como se realizou o capital social
A24: (b) Capital subscrito e ainda não realizado
A26: Rubricas | C26: Saldo inicial | D26: Aumentos | E26: Diminuições | F26: Saldo final
A28: Capital subscrito e não realizado | B28: 35111/35121/35131/35141 | C28: =[1]!SaldoDB([2]Parâmetros!$D$5,[2]Parâmetros!$F$5,"35111","00","00")+[1]!SaldoDB([2]Parâmetros!$D$5,[2]Parâmetros!$F$5,"35121","00","00")+[1]!SaldoDB([2]Parâmetros!$D$5,[2]Parâmetros!$F$5,"35131","00","00")+[1]!SaldoDB([2]Parâmetros!$D$5,[2]Parâmetros!$F$5,"35141","00","00") -> #NAME? | D28: =[1]!MovimDB([2]Parâmetros!$D$5,[2]Parâmetros!$F$5,"35111","01","13")+[1]!MovimDB([2]Parâmetros!$D$5,[2]Parâmetros!$F$5,"35121","01","13")+[1]!MovimDB([2]Parâmetros!$D$5,[2]Parâmetros!$F$5,"35131","01","13")+[1]!MovimDB([2]Parâmetros!$D$5,[2]Parâmetros!$F$5,"35141","01","13") -> #NAME? | E28: =[1]!MovimCR([2]Parâmetros!$D$5,[2]Parâmetros!$F$5,"35111","01","15")-[1]!MovimCR([2]Parâmetros!$D$5,[2]Parâmetros!$F$5,"35121","01","15")-[1]!MovimCR([2]Parâmetros!$D$5,[2]Parâmetros!$F$5,"35131","01","15")-[1]!MovimCR([2]Parâmetros!$D$5,[2]Parâmetros!$F$5,"35141","01","15") -> #NAME? | F28: =+C28+D28-E28 -> #NAME?
A30: ( c) Composição do capital após aumento, no caso da identidade se tratar de uma sociedade anónima
A34: 12.3 Prestações suplementares:
A36: Indicar:
A37: Forma de constituição
A38: Restrições de utilização

Sheet 13 - Reservas
A1: 13. Reservas:
A3: 13.1 - Composição
A4: Rubricas | C4: Saldo inicial | D4: Aumentos | E4: Diminuições | F4: Saldo final
A5: Reserva legal (a) | B5: 55 | C5: 0 | D5: 0 | E5: 0 | F5: =+C5+D5-E5 -> 0
A6: Reservas de reavaliação (b) | B6: 56 | C6: 0 | D6: 0 | E6: 0 | F6: =+C6+D6-E6 -> 0
A7: Reservas com fins especiais ( c) | B7: 57 | C7: 0 | D7: 0 | E7: 0 | F7: =+C7+D7-E7 -> 0
A8: Reservas livres | B8: 58 | C8: 0 | D8: 0 | E8: 0 | F8: =+C8+D8-E8 -> 0
A10: Total | C10: =SUM(C5:C8) -> 0 | D10: =SUM(D5:D8) -> 0 | E10: =SUM(E5:E8) -> 0 | F10: =SUM(F5:F8) -> 0

Sheet 14 - Resultados Transitados
A1: 14. Resultados transitados:
A3: 14.1 composição
A4: Rubricas | C4: Saldo inicial | D4: Aumentos | E4: Diminuições | F4: Saldo final
A5: Saldo inicial:
A6: Movimentos no período:
A7: Transferência dos resultados do exercício anterior | B7: 8111 | C7: 0 | D7: 0 | E7: 0 | F7: =+C7+D7-E7 -> 0
A8: Aplicação de resultados (a) | B8: 8112 | C8: 0 | D8: 0 | E8: 0 | F8: =+C8+D8-E8 -> 0
A9: Erros fundamentais (b) | B9: 8113 | C9: 0 | D9: 0 | E9: 0 | F9: =+C9+D9-E9 -> 0
A10: Alterações de políticas contabilistas (b) | B10: 8114 | C10: 0 | D10: 0 | E10: 0 | F10: =+C10+D10-E10 -> 0
A11: Efeito de impostos dos erros fundamentais e das alterações de políticas contabilísticas (b) | B11: 8115 | C11: 0 | D11: 0 | E11: 0 | F11: =+C11+D11-E11 -> 0
A12: Outros movimentos | C12: 0 | D12: 0 | E12: 0 | F12: =+C12+D12-E12 -> 0
A13: discriminar | C13: 0 | D13: 0 | E13: 0 | F13: =+C13+D13-E13 -> 0
A15: Total | C15: =SUM(C7:C13) -> 0 | D15: =SUM(D7:D13) -> 0 | E15: =SUM(E7:E13) -> 0 | F15: =SUM(F7:F13) -> 0

Sheet 15 - Emp. Corr. não Corr.
A1: 15. Empréstimos correntes e não correntes:
A3: 15.1 Composição
A4: Rubricas | C4: Corrente | D4: Não corrente
D5: Vencível até 5 anos | E5: Vencível a mais de 5 anos | F5: Total
A8: Empréstimos bancários | B8: 3311/3312 | C8: 0 | D8: 0 | E8: 0 | F8: =C8+D8+E8 -> 0
A9: Empréstimos por obrigações | B9: 3321/3322 | C9: 0 | D9: 0 | E9: 0 | F9: =C9+D9+E9 -> 0
A10: Empréstimos por título de participação | B10: 3331/3332 | C10: 0 | D10: 0 | E10: 0 | F10: =C10+D10+E10 -> 0
A11: Outros empréstimos | B11: 3391/3392 | C11: 0 | D11: 0 | E11: 0 | F11: =C11+D11+E11 -> 0
A13: Total | C13: =SUM(C8:C11) -> 0 | D13: =SUM(D8:D11) -> 0 | E13: =SUM(E8:E11) -> 0 | F13: =SUM(F8:F11) -> 0

Sheet 17 - Provisões para Pensões
A1: 17. Provisões para pensões
A3: 17.1 movimentos, ocorridos durante o exercício, nestas provisões:
A4: Rubricas | C4: Saldo inicial | D4: Aumentos | E4: Diminuições | F4: Saldo final
A6: Provisões para pensões | B6: 391 | C6: 0 | D6: 0 | E6: 0 | F6: =+C6+D6-E6 -> 0
A8: Total | B8: 391 | C8: =C6 -> 0 | D8: =D6 -> 0 | E8: =E6 -> 0 | F8: =+C8+D8-E8 -> 0

Sheet 18 - Prov. Out. Riscos e Enc.
A1: 18. Provisões para outros riscos e encargos:
A3: 18.1 Movimentos, ocorridos durante o exercício, nestas provisões:
A4: Rubricas | C4: Saldo inicial | D4: Aumentos | E4: Diminuições | F4: Saldo final
A6: Provisões para processo judiciais em curso | B6: 392 | C6: 0 | D6: 0 | E6: 0 | F6: =+C6+D6-E6 -> 0
A7: Provisões para acidentes de trabalho | B7: 393 | C7: 0 | D7: 0 | E7: 0 | F7: =+C7+D7-E7 -> 0
A8: Provisões para garantias dadas a clientes | B8: 394 | C8: 0 | D8: 0 | E8: 0 | F8: =+C8+D8-E8 -> 0
A9: Provisões para outros riscos e encargos
A10: Descrever a natureza | B10: 3991 | C10: 0 | D10: 0 | E10: 0 | F10: =+C10+D10-E10 -> 0
A12: Total | C12: =SUM(C6:C10) -> 0 | D12: =SUM(D6:D10) -> 0 | E12: =SUM(E6:E10) -> 0 | F12: =SUM(F6:F10) -> 0

Sheet 19 -Outros Act. não C. e C. P.
A1: 19. Outros passivos não correntes e contas a pagar
A3: 19.1 Composição:
A4: Rubricas | C4: Corrente | D4: Não corrente
D5: Vencível até 5 anos | E5: Vencível a mais de 5 anos | F5: Total
A8: Fornecedores - Correntes | B8: 321 | C8: 0 | D8: 0 | E8: 0 | F8: =+D8-E8 -> 0
A9: Fornecedores - titulas a pagar | B9: 322 | C9: 0 | D9: 0 | E9: 0 | F9: =+D9-E9 -> 0
A10: Clientes - saldos credores | C10: 0 | D10: 0 | E10: 0 | F10: =+D10-E10 -> 0
A11: Adiantamentos de clientes | B11: 3191 | C11: 0 | D11: 0 | E11: 0 | F11: =+D11-E11 -> 0
A12: Outros | B12: 3192/3193 | C12: 0 | D12: 0 | E12: 0 | F12: =+D12-E12 -> 0
A13: Estado (a) | B13: 34 | C13: 90000 | D13: 0 | E13: 0 | F13: =+C13 -> 90000
A14: Participantes e participadas | B14: 35 | C14: 0 | D14: 0 | E14: 0 | F14: =+D14-E14 -> 0
A15: Pessoal | B15: 36 | C15: 0 | D15: 0 | E15: 0 | F15: =+D15-E15 -> 0
A16: Credores - compras de imobilizado | B16: 371 | C16: 0 | D16: 0 | E16: 0 | F16: =+D16-E16 -> 0
A17: Outros credores | B17: 3792 | C17: 0 | D17: 0 | E17: 0 | F17: =+D17-E17 -> 0
A19: Total | C19: =SUM(C8:C17) -> 90000 | D19: =SUM(D8:D17) -> 0 | E19: =SUM(E8:E17) -> 0 | F19: =SUM(F8:F17) -> 90000
A22: (a) Esta rubrica tem a seguida composição
A24: Rubricas | C24: 2015 | D24: 2014
A26: Impostos sobre os lucros | C26: 90000 | D26: 0
A28: Adiantamentos | B28: 3412 | C28: 0 | D28: 0
A29: Retenções na fonte | B29: 3413 | C29: 0 | D29: 0
A30: Encargo do ano | B30: 3411 | C30: 0 | D30: 0
A31: Imposto de produção e consumo | B31: 342 | C31: 0 | D31: 0
A32: Imposto de rendimento de trabalho | B32: 343 | C32: 0 | D32: 0
A33: Imposto de circulação | B33: 344 | C33: 0 | D33: 0
A34: Outros impostos | B34: 349 | C34: 0 | D34: 0
A36: Total | C36: =+C26+C31+C32+C33+C34 -> 90000 | D36: =+D26+D31+D32+D33+D34 -> 0

Sheet 20 - Empréstimos de Curto Prazo
A1: 20. Empréstimos de curto prazo
A3: 20.1 Composição e movimentos no período
A4: Rubricas | C4: Saldo inicial | D4: Aumentos | E4: Diminuições | F4: Saldo final
A7: Empréstimos bancários | B7: 3311 | C7: 0 | D7: 0 | E7: 0 | F7: =C7+D7-E7 -> 0
A8: Empréstimos por obrigações | B8: 3321 | C8: 0 | D8: 0 | E8: 0 | F8: =C8+D8-E8 -> 0
A9: Empréstimos por título de participação | B9: 3331 | C9: 0 | D9: 0 | E9: 0 | F9: =C9+D9-E9 -> 0
A10: Outros empréstimos | B10: 3391 | C10: 0 | D10: 0 | E10: 0 | F10: =C10+D10-E10 -> 0
A12: Total | C12: =SUM(C7:C10) -> 0 | D12: =SUM(D7:D10) -> 0 | E12: =SUM(E7:E10) -> 0 | F12: =SUM(F7:F10) -> 0
A15: 20.2 Condições de financiamento
A16: Rubricas | C16: Taxas de juro | D16: Moeda estrangeira | E16: Valor na moeda local
A20: Empréstimos bancários | B20: 3311
A21: Efectuar subdivisões por tipo de moeda estrangeira, se aplicável
A22: Empréstimos por obrigações | B22: 3321
A23: Efectuar subdivisões por tipo de moeda estrangeira, se aplicável
A24: Empréstimos por título de participação | B24: 3331
A25: Efectuar subdivisões por tipo de moeda estrangeira, se aplicável
A26: Outros empréstimos | B26: 3391
A27: Efectuar subdivisões por tipo de moeda estrangeira, se aplicável
A28: Total

Sheet 21 - Outros Passivos Correntes
A1: 21. Outros passivos correntes
A3: 21.1 Composição
A4: Rubricas | C4: 2014 | D4: 2013
A6: Encargos a pagar | C6: 0 | D6: 0
A7: Proveitos a repartir por exercícios futuros | C7: 2081522 | D7: 0
A9: Total | C9: =SUM(C6:C7) -> 2081522 | D9: =SUM(D6:D7) -> 0

Sheet 22 - Vendas
A1: 22. Vendas
A3: 22.1 Composição das vendas por mercados
A4: Rubricas | C4: 2014 | D4: 2013
A6: Mercado interno | C6: =+C7+C8 -> 6739290 | D6: =+D7+D8 -> 0
A7: Vendas | B7: 6111/6121/6131/6141/6171/6181 | C7: 6739290 | D7: 0
A8: Subsídios a preços | B8: 615 | C8: 0 | D8: 0
A9: Mercado externo | B9: 6112/6122/6132/6142 | C9: 0 | D9: 0
A11: Total | C11: =+C9+C6 -> 6739290 | D11: =+D9+D6 -> 0

Sheet 23 - Prestação de Serviço
A1: 23. Prestação de serviço:
A3: 23.1 Composição das prestações de serviço por mercados
A4: Rubricas | C4: 2015 | D4: 2014
A6: Mercado interno | B6: 6211/6221/6281 | C6: 878850 | D6: 0
A7: Mercado externo | B7: 6212/6222/6282 | C7: 0 | D7: 0
A9: Total | C9: =+C6+C7 -> 878850 | D9: =+D6+D7 -> 0
A11: 23.2 Composição das prestações de serviço por actividades
A12: Rubricas | C12: =[2]Parâmetros!$F$5 -> 2012 | D12: =[2]Parâmetros!$F$6 -> 2011
A14: Serviços principais
A15: Enumerar por tipo de actividade
A17: Serviços secundários
A18: Enumerar por tipo de actividade
A19: Total | C19: =SUM(C14:C18) -> 0 | D19: =SUM(D14:D18) -> 0

Sheet 24 - Outros Proveitos Op.
A1: 24. Outros proveitos operacionais
A3: 24.1 Composição
A4: Rubricas | C4: =[2]Parâmetros!$F$5 -> 2012 | D4: =[2]Parâmetros!$F$6 -> 2011
A6: Serviços suplementares | B6: 631 | C6: 0 | D6: 0
A7: Royalties | B7: 632 | C7: 0 | D7: 0
A8: Subsídios à exploração (a) | B8: 633 | C8: 0 | D8: 0
A9: Subsídios a investimentos (b) | B9: 634 | C9: 0 | D9: 0
A10: Outros proveitos e ganhos operacionais | B10: 638 | C10: 0 | D10: 0
A12: Total | C12: =SUM(C6:C10) -> 0 | D12: =SUM(D6:D10) -> 0
A14: (a) Subsídios à exploração:
A15: Indicar:
A16: Natureza do subsidio
A17: Condições não satisfeitas
A18: Contingências decorrentes de condições não satisfeitas.
A20: (a) Subsídios a investimentos:
A21: Indicar:
A22: Natureza do subsidio
A23: Condições não satisfeitas
A24: Contingências decorrentes de condições não satisfeitas.

Sheet 25 - Var. nos Prod. Ac. Vias F.
A1: 25. Variação nos produtos acabados e em vias de fabrico:
A2: Rubricas | C2: Existências iniciais | D2: Aumentos | E2: Existências finais | F2: Variação no ano
A5: Produtos e trabalhos em curso | B5: 23 | C5: 0 | D5: 0 | E5: 0 | F5: =+E5+C5+D5 -> 0
A6: Produtos acabados e intermédios | B6: 24 | C6: 0 | D6: 0 | E6: 0 | F6: =+E6-C6-D6 -> 0
A7: Subprodutos, desperdício, resíduos e refugos | B7: 25 | C7: 0 | D7: 0 | E7: 0 | F7: =+E7-C7-D7 -> 0
A9: Total | C9: =SUM(C5:C7) -> 0 | D9: =SUM(D5:D7) -> 0 | E9: =SUM(E5:E7) -> 0 | F9: =SUM(F5:F7) -> 0

Sheet 26 - Trab. para Própria Emp.
A1: 26. Trabalhos para a própria empresa:
A2: Rubricas | C2: =[2]Parâmetros!$F$5 -> 2012 | D2: =[2]Parâmetros!$F$6 -> 2011
A4: Trabalhos para imobilizado | C4: =SUM(C6:C8) -> 0 | D4: =SUM(D6:D8) -> 0
A6: Corpóreo | B6: 6511 | C6: 0 | D6: 0
A7: Incorpóreo | B7: 6512 | C7: 0 | D7: 0
A8: Investimentos financeiros | B8: 6513 | C8: 0 | D8: 0
A10: Trabalhos para existências | C10: 0 | D10: 0
A11: Trabalhos para encargos a repartir por exercícios futuros | B11: 652 | C11: 0 | D11: 0
A13: Total | C13: =+C11+C10+C4 -> 0 | D13: =+D11+D10+D4 -> 0

Sheet 27 - CEVMP e SC
A1: 27. Custos das existências vendidas e das matérias primas e subsidiárias consumidas
A2: Rubricas | C2: Existências iniciais | D2: Compras | E2: Ofertas e perdas ou ganhos | F2: Existências finais | G2: Custo no ano
A5: Matérias-primas, subsidiárias e de consumo | B5: 22/211/2171/2181 | C5: 0 | D5: 0 | E5: 0 | F5: 0 | G5: =+C5+D5-E5-F5 -> 0
A6: Materiais Diversos | B6: 26/212/2172/2182 | C6: 0 | D6: 0 | E6: 0 | F6: 0 | G6: =C6+D6-F6-E6 -> 0
A7: Mercadorias
A9: Total | C9: =SUM(C5:C7) -> 0 | D9: =SUM(D5:D7) -> 0 | E9: =SUM(E5:E7) -> 0 | F9: =SUM(F5:F7) -> 0 | G9: =SUM(G5:G6) -> 0

Sheet 28 - Custo com o Pessoal
A1: 28. Custos com o pessoal:
A2: Rubricas | C2: 2015 | D2: 2014
A4: Remunerações-Orgãos sociais | B4: 721 | C4: 0 | D4: 0
A5: Remunerações-Pessoal | B5: 723 | C5: 200000 | D5: 0
A6: Encargos sobre remunerações | B6: 724 | C6: 0 | D6: 0
A7: Seguros acidente trab. Doenç. Profissionais | C7: 0 | D7: 0
A8: Outras despesas com o pessoal | B8: 722 | C8: 0 | D8: 0
A9: Formação | C9: 0 | D9: 0
A10: Assistência médica | C10: 0 | D10: 0
A11: Indemnização por despedimento | C11: 0 | D11: 0
A13: Total | C13: =SUM(C4:C11) -> 200000 | D13: =SUM(D4:D11) -> 0

Sheet 29 - Amortizações
A1: 29. Amortizações
A2: Rubricas | C2: 2014 | D2: 2013
A4: Imobilizações corpóreas (Nota 4) | B4: 731 | C4: 0 | D4: 0
A5: Imobilizações incorpóreas (Nota 5) | B5: 732 | C5: 93826.95 | D5: 0
A7: Total | C7: =SUM(C4:C5) -> 93826.95 | D7: =SUM(D4:D5) -> 0

Sheet 30 - Outros Custos e Perdas Op.
A1: 30. Outros custos e perdas operacionais
A2: Rubricas | C2: 2015 | D2: 2014
A4: Subcontratos | B4: 751 | C4: 0 | D4: 0
A5: Fornecimentos e serviços de terceiros | B5: 752 | C5: 378850 | D5: 0
A7: Despesas de investigação | C7: 0 | D7: 0
A8: Despesas de desenvolvimento | C8: 0 | D8: 0
A9: Conservação e reparação | B9: 752142/75226 | C9: 0 | D9: 0
A10: Royalties | B10: 75235 | C10: 0 | D10: 0
A11: Outros | C11: =C5-SUM(C7:C9) -> 378850 | D11: =D5-SUM(D7:D9) -> 0
A13: Impostos | B13: 753 | C13: 0 | D13: 0
A14: Despesas confidenciais | B14: 754 | C14: 0 | D14: 0
A15: Quotizações | B15: 755 | C15: 0 | D15: 0
A16: Ofertas e amostras de existências | B16: 756 | C16: 0 | D16: 0
A17: Custos e perdas operacionais | B17: 758 | C17: 0 | D17: 0
A19: Total | C19: =+C4+C5+SUM(C13:C17) -> 378850 | D19: =+D4+D5+SUM(D13:D17) -> 0

Sheet 31 - Resultados Financeiros
A1: 31. Resultados financeiros:
A2: Rubricas | C2: 2014 | D2: 2013
A4: Proveitos e ganhos financeiros | C4: =+C7+C9+C12+C15+C18+C23+C26+C24 -> 0 | D4: =+D7+D9+D12+D15+D18+D23+D25 -> 0
A6: Juros | B6: 661 | C6: 0 | D6: 0
A7: Investimentos financeiros | B7: 6611 | C7: 0 | D7: 0
A8: Outros | C8: 0 | D8: 0
A9: Rendimentos de investimentos em imóveis | B9: 664 | C9: 0 | D9: 0
A10: Investimentos financeiros | B10: 6641 | C10: 0 | D10: 0
A11: Outros | C11: 0 | D11: 0
A12: Rendimentos de participações de capital | B12: 665 | C12: 0 | D12: 0
A13: Investimentos financeiros | B13: 6651 | C13: 0 | D13: 0
A14: Outros | C14: 0 | D14: 0
A15: Ganhos na alienação de participações financeiras | B15: 666 | C15: 0 | D15: 0
A16: Investimentos financeiros | B16: 6661 | C16: 0 | D16: 0
A17: Outros | C17: =C15-C16 -> 0 | D17: 0
A18: Reposição de provisões) | B18: 667 | C18: 0 | D18: 0
A19: Investimentos em filiais e associadas (Nota 6) | B19: 66711/66712 | C19: 0 | D19: 0
A20: Outros activos financeiros (nota 7) | B20: 66713/66714/66719 | C20: 0 | D20: 0
A21: Disponibilidade (Nota 10) | B21: 6672 | C21: 0 | D21: 0
A22: Diferenças de câmbio favoráveis | B22: 662 | C22: 0 | D22: 0
A23: Realizadas | B23: 6621 | C23: 0 | D23: 0
A24: Não realizadas | C24: 0 | D24: 0
A25: Descontos de pronto pagamento obtidos em imóveis | B25: 663 | C25: 0 | D25: 0
A26: Outros | C26: 0
A28: Custos e perdas financeiros | C28: 3321.7 | D28: =+D30+D31+D32+D36+D42+D40+D43 -> 0
A30: Juros | B30: 761 | C30: 0 | D30: 0
A31: Amortizações de investimentos em imóveis | B31: 764 | C31: 0 | D31: 0
A32: provisões para aplicações financeiras | B32: 765 | C32: 0 | D32: 0
A33: Investimentos em filiais e associadas (Nota 6) | B33: 76511/76512 | C33: 0 | D33: 0
A34: Outros activos financeiros (Nota 7) | B34: 76512/76514/76519 | C34: 0 | D34: 0
A35: Disponibilidade (Nota 10) | B35: 7652 | D35: 0
A36: Perdas na alienação de aplicações financeiras | B36: 766 | C36: 0 | D36: 0
A37: Investimentos financeiros | B37: 7661 | C37: 0 | D37: 0
A38: Outros | B38: 7662 | C38: 0 | D38: 0
A39: Diferenças de câmbio desfavoráveis | B39: 762 | C39: 0 | D39: 0
A40: Realizadas | B40: 7621 | C40: 0 | D40: 0
A41: Não realizadas | B41: 7622 | C41: 0 | D41: 0
A42: Descontos de pronto pagamento obtidos em imóveis | B42: 763 | C42: 0 | D42: 0
A43: Outros | B43: 767 | C43: 0 | D43: 0
A45: Total | C45: =+-C28 -> -3321.7 | D45: =D4-D28 -> 0

Sheet 32 - Res. de Filiais Associadas
A1: 32. Resultados de filiais e associadas:
A2: Rubricas | C2: =[2]Parâmetros!$F$5 -> 2012 | D2: =[2]Parâmetros!$F$6 -> 2011
A4: Subsidiárias | B4: 6711 | C4: 0 | D4: 0
A6: Dividendos
A7: Lucros
A9: Associadas | B9: 6712 | C9: 0 | D9: 0
A11: Dividendos
A12: Lucros
A14: Total | C14: =+C4+C9 -> 0 | D14: =+D4+D9 -> 0

Sheet 33 - Res. não Operacionais
A1: 33. Resultados não operacionais:
A2: Rubricas | C2: 2012 | D2: 2011
A4: Proveitos e ganhos não operacionais | B4: 68 | C4: =+C6+SUM(C10:C18) -> 0 | D4: =+D6+SUM(D10:D18) -> 0
A6: Reposição de provisões | B6: 6801 | C6: 0 | D6: 0
A7: Existências (Nota 8) | B7: 68011 | C7: 0 | D7: 0
A8: Cobranças duvidosas (Nota 9) | B8: 68012 | C8: 0 | D8: 0
A9: Outros riscos e encargos (Nota 18) | B9: 68013 | C9: 0 | D9: 0
A10: Anulação de amortizações extraordinárias | B10: 6802 | C10: 0 | D10: 0
A11: Ganhos em imobilizações | B11: 6803 | C11: 0 | D11: 0
A12: Ganhos em existências | B12: 6804 | C12: 0 | D12: 0
A13: Recuperação de dívidas | B13: 6805 | C13: 0 | D13: 0
A14: Benefícios de penalidades contratuais | B14: 6806 | C14: 0 | D14: 0
A15: Descontinuidade de operações | B15: 6808 | C15: 0 | D15: 0
A16: Alterações de politicas contabilísticas | B16: 6809 | C16: 0 | D16: 0
A17: Correcções relativas a exercícios anteriores | B17: 6810 | C17: 0 | D17: 0
A18: Outros proveitos e ganhos não operacionais | B18: 6811 | C18: 0 | D18: 0
A20: Custos e perdas não operacionais | B20: 78 | C20: =+C22+SUM(C27:C36) -> 0 | D20: =+D22+SUM(D27:D36) -> 0
A22: Provisões | B22: 7801 | C22: 0 | D22: 0
A24: Existências (Nota 8) | B24: 78011 | C24: 0 | D24: 0
A25: Cobranças duvidosas (Nota 9) | B25: 78012 | C25: 0 | D25: 0
A26: Outros riscos e encargos (Nota 18) | B26: 78013 | C26: 0 | D26: 0
A27: Amortizações extraordinárias | B27: 7802 | C27: 0 | D27: 0
A28: Perdas em imobilizações | B28: 7803 | C28: 0 | D28: 0
A29: Perdas em existências | B29: 7804 | C29: 0 | D29: 0
A30: Dividas incobráveis | B30: 7805 | C30: 0 | D30: 0
A31: Multas e penalidades contratuais | B31: 7806 | C31: 0 | D31: 0
A32: Custos de reestruturação | B32: 7807 | C32: 0 | D32: 0
A33: Descontinuidade de operações | B33: 7808 | C33: 0 | D33: 0
A34: Alterações de politicas contabilísticas | B34: 7809 | C34: 0 | D34: 0
... A36: Outros custos e perdas não operacionais | B36: 7811 | C36: 0 | D36: 0
A38: Total | C38: =+C4-C20 -> 0 | D38: =+D4-D20 -> 0

Sheet 34 - Resultados Extraordinários
A1: 34. Resultados extraordinários
A2: Rubricas | C2: 2012 | D2: 2011
A4: Proveitos e ganhos extraordinários | B4: 69 | C4: =SUM(C6:C11) -> 20000 | D4: =SUM(D6:D11) -> 0
A6: Catástrofes naturais | B6: 691 | C6: 20000 | D6: 0
A7: Convulsões políticas | B7: 692 | C7: 0 | D7: 0
A8: Expropriações | B8: 693 | C8: 0 | D8: 0
A9: Sinistros | B9: 694 | C9: 0 | D9: 0
A10: Subsídios (a) | B10: 695 | C10: 0 | D10: 0
A11: Anulação de passivos não exigíveis | B11: 696 | C11: 0 | D11: 0
A13: Custos e perdas extraordinárias | B13: 79 | C13: =SUM(C15:C19) -> 0 | D13: =SUM(D15:D19) -> 0
A15: Catástrofes naturais | B15: 791 | C15: 0 | D15: 0
A16: Convulsões políticas | B16: 792 | C16: 0 | D16: 0
A17: Expropriações | B17: 793 | C17: 0 | D17: 0
A18: Sinistros | B18: 794 | C18: 0 | D18: 0
A19: Outros
A21: Total | C21: =+C4-C13 -> 20000 | D21: =+D4-D13 -> 0

Sheet 35 - Imposto Sobre o Rendimento
A1: 35. Imposto sobre o rendimento
A2: Rubricas | C2: 2014 | D2: 2013
A4: Resultado contabilístico | B4: 88 | C4: -496177.38 | D4: 0
A6: Correcções para efeitos fiscais | C6: 0 | D6: 0
A7: A somar: Variações patrimoniais positivas
A9: Custos e perdas não aceites para efeitos fiscais | C9: 0 | D9: 0
A10: Discriminar
A12: A deduzir: Variações patrimoniais negativas | C12: 0 | D12: 0
A14: Proveitos e ganhos não tributáveis | C14: 0 | D14: 0
A15: Discriminar
A16: Prejuízos fiscais de anos anteriores | C16: 0 | D16: 0
A17: Lucros levados a reservas e reinvestidos
A19: Lucro tributável (prejuízo fiscal) | C19: 0 | D19: =D4-D16 -> 0
A20: Taxa nominal de impostos | C20: 0.3 | D20: 0.35
A22: Imposto sobre os lucros(a) | C22: =C19*C20 -> 0 | D22: =D19*D20 -> 0
A24: Imposto industrial Lei 7/97 | C24: 0 | D24: 0
A26: Provisórias | C26: 0 | D26: 0
A28: Imposto a pagar | C28: =C22-C24-C26 -> 0 | D28: =D22-D24-D26 -> 0

Sheet 36 - Resp. Assumidas e não R.
A1: 36. Responsabilidades assumidas e não reflectidas no balanço:
A2: Rubricas | C2: =[2]Parâmetros!$F$5 -> 2012 | D2: =[2]Parâmetros!$F$6 -> 2011
A4: Garantias | C4: 0 | D4: 0
A5: Avales | C5: 0 | D5: 0
A6: Letras descontadas | C6: 0 | D6: 0
A7: Outras | C7: 0 | D7: 0
A8: Discriminar o tipo de garantias prestadas
A10: Total

Sheet Imp Ind. Marvine Lda
A1: Excerto do Modelo n.º 1 Código de Imposto Industrial | D1: MARVINE, LDA | E1: 2012
A2: 2 | B2: DEMONSTRAÇÃO DE RESULTADOS
A3: N.º | B3: DESIGNAÇÃO | C3: CONTA PGC | D3: EXERCÍCIO CORRENTE | E3: EXERCÍCIO ANTERIOR
A4: 2.1 | B4: Proveitos e Ganhos por Natureza | C4: 6 | D4: =+SUM(D5:D8) -> 0 | E4: =+SUM(E5:E8) -> 0
A5: 2.1.1 | B5: Vendas de produtos | C5: 6.1.1/2 | D5: 0 | E5: 0
A6: 2.1.2 | B6: Vendas de mercadorias | C6: 6.1.3 | D6: 0 | E6: 0
A7: 2.1.3 | B7: Prestações de serviços | C7: 62 | D7: 0 | E7: 0
A8: 2.1.4 | B8: Outros proveitos operacionais | C8: 63 | D8: 0 | E8: 0
A10: A | B10: Soma dos Proveitos Operacionais | D10: =SUM(D5:D8) -> 0 | E10: =SUM(E5:E8) -> 0
A11: 2.1.5 | B11: Variação nos inventários de pro. acab. e prod. curso | C11: 64 | D11: 0 | E11: 0
A12: 2.1.6 | B12: Trabalhos para a própria empresa | C12: 65 | D12: 0 | E12: 0
A13: 2.1.7 | B13: Proveitos e ganhos financeiros gerais | C13: 66 | D13: 0 | E13: 0
A14: 2.1.8 | B14: Proveitos e ganhos financeiros em filiais e assoc. | C14: 67 | D14: 0 | E14: 0
A15: 2.1.9 | B15: Outros proveitos e ganhos não operacionais | C15: 68 | D15: 0 | E15: 0
A16: 2.2.0 | B16: Proveitos e ganhos extraordinários | C16: 69 | D16: 0 | E16: 0
A18: B | B18: Soma de Outros Proveitos e Ganhos não Operacionais | D18: =+SUM(D11:D16) -> 0 | E18: =+SUM(E11:E16) -> 0
A19: C | B19: TOTAL DOS PROVEITOS (A + B) | D19: =+D10+D18 -> 0 | E19: =+E10+E18 -> 0
A20: 2.2 | B20: Custos e perdas por Natureza | C20: 7 | D20: =+SUM(D21:D31) -> 0 | E20: =+SUM(E21:E31) -> 0
A21: 2.2.1 | B21: Custo das mercadorias vendidas e mat. consumidas | C21: 71 | D21: 0 | E21: 0
A22: 2.2.2 | B22: Custos com o pessoal | C22: 72 | D22: 0 | E22: 0
A23: 2.2.3 | B23: Amortizações do exercício | C23: 73 | D23: 0 | E23: 0
A24: 2.2.4 | B24: Sub-contratos | C24: 75.1 | D24: 0 | E24: 0
A25: 2.2.5 | B25: Fornecimentos e serviços de terceiros | C25: 75.2 | D25: 0 | E25: 0
A26: 2.2.6 | B26: Impostos | C26: 75.3 | D26: 0 | E26: 0
A27: 2.2.7 | B27: Outros custos e perdas operacionais | C27: 75.8 | D27: 0 | E27: 0
A28: 2.2.8 | B28: Custos e perdas financeiras gerais | C28: 76 | D28: 0 | E28: 0
A29: 2.2.9 | B29: Custos e perdas financeiras em filiais e associadas | C29: 77 | D29: 0 | E29: 0
A30: 2.3.0 | B30: Outros custos e perdas não operacionais | C30: 78 | D30: 0 | E30: 0
A31: 2.3.1 | B31: Custos e perdas extraordinárias | C31: 79 | D31: 0 | E31: 0
A33: D | B33: TOTAL DOS CUSTOS | D33: =+SUM(D21:D31) -> 0 | E33: =+SUM(E21:E31) -> 0
A34: E | B34: Resultado antes de impostos (C - D) | D34: =+D19-D33 -> 0 | E34: =+E19-E33 -> 0
A35: F | B35: Impostos sobre os lucros | D35: 0 | E35: 0
A36: G | B36: RESULTADO LÍQUIDO DO EXERCÍCIO (E-F) | D36: =+D34-D35 -> 0 | E36: =+E34-E35 -> 0
A38: 5 | B38: APURAMENTO DO LUCRO TRIBUTÁVEL
B39: DESIGNAÇÃO | D39: EXERCÍCIO CORRENTE | E39: EXERCÍCIO CORRENTE
A40: A ACRESCER | B40: Prémios de seguro de vida (artigo 25º CII) | D40: 0 | E40: 0
B41: Amortizações excessivas (artigo 29º e 31º CII) | D41: 0 | E41: 0
B42: Provisões excessivas (artigo 36º CII) | D42: 0 | E42: 0
B43: Provisões não previstas (artigo36º CII) | D43: 0 | E43: 0
B44: Donativos excedentes aos previstos no (artigo 39º CII) | D44: 0 | E44: 0
...

Sheet Folha1
